<?xml version="1.0" encoding="utf-8"?>
<!-- This URDF was automatically created by SolidWorks to URDF Exporter! Originally created by Stephen Brawner (brawner@gmail.com) 
     Commit Version: 1.5.1-0-g916b5db  Build Version: 1.5.7152.31018
     For more information, please see http://wiki.ros.org/sw_urdf_exporter -->
<robot name="myrobot" xmlns:xacro="http://ros.org/wiki/xacro">
  <xacro:include filename="$(find p31)/textures/material.xacro"/>
  <xacro:include filename="$(find p31)/urdf/sensor.gazebo.xacro"/>
   
   <xacro:property name="r200_cam_rgb_py" value="0.005"/>
  <xacro:property name="r200_cam_rgb_px" value="0.018"/>
  <xacro:property name="r200_cam_rgb_pz" value="0.013"/>
  <xacro:property name="r200_cam_depth_offset" value="0.01"/>
  
  <link name="dummy_link"/>
  
  <joint name="dummy" type="fixed">
	<origin xyz="0 0 0" rpy="0 0 0"/>
	<parent link="dummy_link"/>
	<child link="base_link"/>
  </joint>
  
  <link name="base_link">
    <inertial>
      <origin xyz="0 0 0.075" rpy="0 0 0" />
      <mass
        value="4.29523826658563" />
      <inertia
        ixx="0.0140228837555786" ixy="-2.64590782478008E-07" ixz="1.1976585966069E-06"
        iyy="0.0338909845733869" iyz="-1.01962911408937E-07"
        izz="0.0213701972603812" />
    </inertial>
    <visual>
      <origin xyz="0 0 0" rpy="0 0 0" />
      <geometry>
        <mesh filename="package://p31/meshes/base_link.STL" />
      </geometry>
      <material name="">
        <color rgba="0.752941176470588 0.752941176470588 0.752941176470588 1" />
      </material>
    </visual>
    <collision>
      <origin xyz="0 0 0" rpy="0 0 0" />
      <geometry>
        <mesh filename="package://p31/meshes/base_link.STL" />
      </geometry>
    </collision>
  </link>
  
  <link name="suspension1">
    <inertial>
      <origin xyz="-0.000780007183144651 0.0205097222143209 -0.0068599226721715" rpy="0 0 0" />
      <mass value="0.102867975835406" />
      <inertia
        ixx="3.45505642878179E-05"  ixy="1.5645477317528E-07"  ixz="2.96411876510939E-09"
        iyy="5.04392109779442E-05"  iyz="1.64845302056396E-08"
        izz="4.20892495598477E-05" />
    </inertial>
    <visual>
      <origin xyz="0 0 0" rpy="0 0 0" />
      <geometry>
        <mesh  filename="package://p31/meshes/suspension1.STL" />
      </geometry>
      <material name="">
        <color rgba="0.752941176470588 0.752941176470588 0.752941176470588 1" />
      </material>
    </visual>
    <collision>
      <origin xyz="0 0 0" rpy="0 0 0" />
      <geometry>
        <mesh filename="package://p31/meshes/suspension1.STL" />
      </geometry>
    </collision>
  </link>
  
  <joint name="suspension_joint1" type="prismatic">
    <origin  xyz="0.135 -0.09 0.080496"  rpy="-3.1416 0 1.5708" />
    <parent link="base_link" />
    <child link="suspension1" />
    <axis xyz="0 0 1" />
    <limit  lower="0" upper="0.1" effort="0" velocity="0" />
  </joint>
  
  <link name="wheel1">
    <inertial>
      <origin xyz="-7.494E-16 0.0081775 1.5266E-16" rpy="0 0 0" />
      <mass value="0.23655" />
      <inertia  ixx="0.00039661" ixy="3.2785E-19" ixz="4.0658E-20"
					iyy="0.00076902"  iyz="-7.0588E-20"
					izz="0.00039661" />
    </inertial>
    <visual>
      <origin xyz="0 0 0" rpy="0 0 0" />
      <geometry>
        <mesh
          filename="package://p31/meshes/wheel1.STL" />
      </geometry>
      <material
        name="">
        <color
          rgba="0 0.50196 1 0.32" />
      </material>
    </visual>
    <collision>
      <origin
        xyz="0 0 0"
        rpy="0 0 0" />
      <geometry>
        <mesh
          filename="package://p31/meshes/wheel1.STL" />
      </geometry>
    </collision>
  </link>
  <joint
    name="wheel_joint1"
    type="continuous">
    <origin
      xyz="-0.0133 0.043 0.00020079"
      rpy="0 0.5236 0" />
    <parent
      link="suspension1" />
    <child
      link="wheel1" />
    <axis
      xyz="0 1 0" />
    <limit
      effort="3.1"
      velocity="7" />
  </joint>
  <link
    name="suspension2">
    <inertial>
      <origin
        xyz="-0.000780007183144901 -0.0205097222143207 -0.00699762293412363"
        rpy="0 0 0" />
      <mass
        value="0.102867975835406" />
      <inertia
        ixx="3.45505642878179E-05"
        ixy="-1.56454773175154E-07"
        ixz="-2.96411876511686E-09"
        iyy="5.04392109779442E-05"
        iyz="1.64845302058301E-08"
        izz="4.20892495598477E-05" />
    </inertial>
    <visual>
      <origin
        xyz="0 0 0"
        rpy="0 0 0" />
      <geometry>
        <mesh
          filename="package://p31/meshes/suspension2.STL" />
      </geometry>
      <material
        name="">
        <color
          rgba="0.752941176470588 0.752941176470588 0.752941176470588 1" />
      </material>
    </visual>
    <collision>
      <origin
        xyz="0 0 0"
        rpy="0 0 0" />
      <geometry>
        <mesh
          filename="package://p31/meshes/suspension2.STL" />
      </geometry>
    </collision>
  </link>
  <joint
    name="suspension_joint2"
    type="prismatic">
    <origin
      xyz="-0.135 -0.09 0.080496"
      rpy="3.1416 0 1.5708" />
    <parent
      link="base_link" />
    <child
      link="suspension2" />
    <axis
      xyz="0 0 1" />
    <limit
      lower="0"
      upper="0.1"
      effort="0"
      velocity="0" />
  </joint>
  <link
    name="wheel2">
    <inertial>
      <origin
        xyz="9.992E-16 0.0081775 -8.0491E-16"
        rpy="0 0 0" />
      <mass
        value="0.23655" />
      <inertia
        ixx="0.00039661"
        ixy="2.5118E-19"
        ixz="1.4954E-23"
        iyy="0.00076902"
        iyz="3.8054E-20"
        izz="0.00039661" />
    </inertial>
    <visual>
      <origin
        xyz="0 0 0"
        rpy="0 0 0" />
      <geometry>
        <mesh
          filename="package://p31/meshes/wheel2.STL" />
      </geometry>
      <material
        name="">
        <color
          rgba="0 0.50196 1 0.32" />
      </material>
    </visual>
    <collision>
      <origin
        xyz="0 0 0"
        rpy="0 0 0" />
      <geometry>
        <mesh
          filename="package://p31/meshes/wheel2.STL" />
      </geometry>
    </collision>
  </link>
  <joint
    name="wheel_joint2"
    type="continuous">
    <origin
      xyz="-0.0133 -0.043 ${-0.00020079-0.00041}"
      rpy="3.1416 1.5708 0" />
    <parent
      link="suspension2" />
    <child
      link="wheel2" />
    <axis
      xyz="0 -1 0" />
    <limit
      effort="3.1"
      velocity="7" />
  </joint>
  <link
    name="suspension3">
    <inertial>
      <origin
        xyz="-1.02730324247346E-13 0.015 -1.0547118733939E-15"
        rpy="0 0 0" />
      <mass
        value="0.00235619449019234" />
      <inertia
        ixx="1.91440802328128E-07"
        ixy="-3.41495302512105E-40"
        ixz="0"
        iyy="2.94524311274043E-08"
        iyz="3.0603630879953E-40"
        izz="1.91440802328128E-07" />
    </inertial>
    <visual>
      <origin
        xyz="0 0 0"
        rpy="0 0 0" />
      <geometry>
        <mesh
          filename="package://p31/meshes/suspension3.STL" />
      </geometry>
      <material
        name="">
        <color
          rgba="0.792156862745098 0.819607843137255 0.933333333333333 1" />
      </material>
    </visual>
    <collision>
      <origin
        xyz="0 0 0"
        rpy="0 0 0" />
      <geometry>
        <mesh
          filename="package://p31/meshes/suspension3.STL" />
      </geometry>
    </collision>
  </link>
  <joint
    name="suspension_joint3"
    type="prismatic">
    <origin
      xyz="0 0.175 0.069998"
      rpy="1.5708 0 0" />
    <parent
      link="base_link" />
    <child
      link="suspension3" />
    <axis
      xyz="0 -1 0" />
    <limit
      lower="0"
      upper="0.1"
      effort="0"
      velocity="0" />
  </joint>
  <link
    name="wheel3">
    <inertial>
      <origin
        xyz="-9.9925E-14 -2.3807E-14 1.3323E-15"
        rpy="0 0 0" />
      <mass
        value="0.14667" />
      <inertia
        ixx="6.1968E-05"
        ixy="2.422E-21"
        ixz="0"
        iyy="6.1968E-05"
        iyz="4.2352E-22"
        izz="6.1968E-05" />
    </inertial>
    <visual>
      <origin
        xyz="0 0 0"
        rpy="0 0 0" />
      <geometry>
        <mesh
          filename="package://p31/meshes/wheel3.STL" />
      </geometry>
      <material
        name="">
        <color
          rgba="1 1 1 1" />
      </material>
    </visual>
    <collision>
      <origin
        xyz="0 0 0"
        rpy="0 0 0" />
      <geometry>
        <mesh
          filename="package://p31/meshes/wheel3.STL" />
      </geometry>
    </collision>
  </link>
  <joint
    name="wheel_joint3"
    type="fixed">
    <origin
      xyz="0 -0.032113 0"
      rpy="-0.036641 -0.028589 -0.23329" />
    <parent
      link="suspension3" />
    <child
      link="wheel3" />
    <axis
      xyz="0.028585 -0.036618 0.99892" />
  </joint>
  <link
    name="second">
    <inertial>
      <origin
        xyz="-1.42345813968723E-06 0.00249999999999997 -2.18320310890574E-06"
        rpy="0 0 0" />
      <mass
        value="0.468125" />
      <inertia
        ixx="0.00412095230208333"
        ixy="-3.42490512735225E-21"
        ixz="-4.39001294694143E-19"
        iyy="0.00688180308333333"
        iyz="1.08557597279624E-22"
        izz="0.00276280130208333" />
    </inertial>
    <visual>
      <origin
        xyz="0 0 0"
        rpy="0 0 0" />
      <geometry>
        <mesh
          filename="package://p31/meshes/second.STL" />
      </geometry>
      <material
        name="">
        <color
          rgba="0.901960784313726 0.901960784313726 0.858823529411765 0.32" />
      </material>
    </visual>
    <collision>
      <origin
        xyz="0 0 0"
        rpy="0 0 0" />
      <geometry>
        <mesh
          filename="package://p31/meshes/second.STL" />
      </geometry>
    </collision>
  </link>
  <joint
    name="second_joint"
    type="fixed">
    <origin
      xyz="0 0 0.18"
      rpy="1.5708 0 0" />
    <parent
      link="base_link" />
    <child
      link="second" />
    <axis
      xyz="0 0 0" />
  </joint>

  <link name="lidar">
	<visual>
		<origin xyz="0 0 0.01" rpy="0 0 0"/>
		<geometry>
			<cylinder radius="0.01" length="0.02"/>
		</geometry>
	</visual>
  </link>
  
  <joint name="lidar_joint" type="fixed">
	<origin xyz="-0.00053 -0.00579 ${0.25173+0.03}" rpy="0 0 0"/>\
	<parent link="base_link"/>
	<child link="lidar"/>
  </joint>
  
  <link name="imu_link">
	<visual>
		<origin xyz="0 0 0.01" rpy="0 0 0"/>
		<geometry>
			<cylinder radius="0.01" length="0.02"/>
		</geometry>
	</visual>
  </link>
  
  <joint name="imu_joint" type="fixed">
	<origin xyz="-0.00053 -0.00579 0.25173" rpy="0 0 0"/>\
	<parent link="base_link"/>
	<child link="imu_link"/>
  </joint>
  
   <joint name="camera_joint" type="fixed">
    <origin xyz="0.0 ${-0.15355-0.01} 0.20128" rpy="0 0 -1.5707"/>
    <parent link="base_link"/>
    <child link="camera_link"/>
  </joint>

  <link name="camera_link">
    <visual>
     <origin xyz="0 0 0" rpy="0 0 0"/>
      <geometry>
       <box size="0.02 0.02 0.02" />
      </geometry>
    </visual>
  </link>
  
  <joint name="camera_rgb_joint" type="fixed">
    <origin xyz="${r200_cam_rgb_px} ${r200_cam_rgb_py} ${r200_cam_rgb_pz}" rpy="0 0 0"/>
    <parent link="camera_link"/>
    <child link="camera_rgb_frame"/>
  </joint>
  <link name="camera_rgb_frame"/>

  <joint name="camera_rgb_optical_joint" type="fixed">
    <origin xyz="0 0 0" rpy="-1.57 0 -1.57"/>
    <parent link="camera_rgb_frame"/>
    <child link="camera_rgb_optical_frame"/>
  </joint>
  <link name="camera_rgb_optical_frame"/>

  <joint name="camera_depth_joint" type="fixed">
    <origin xyz="${r200_cam_rgb_px+r200_cam_depth_offset} ${r200_cam_rgb_py} ${r200_cam_rgb_pz}" rpy="0 0 0"/>
    <parent link="camera_link"/>
    <child link="camera_depth_frame"/>
  </joint>
  <link name="camera_depth_frame"/>

  <joint name="camera_depth_optical_joint" type="fixed">
    <origin xyz="0 0 0" rpy="-1.57 0 -1.57"/>
    <parent link="camera_depth_frame"/>
    <child link="camera_depth_optical_frame"/>
  </joint>
  <link name="camera_depth_optical_frame"/>
  <!--2-->
  <joint name="camera_joint2" type="fixed">
    <origin xyz="0.0 -0.08228 ${0.19695}" rpy="0 1.5707 -1.5707"/>
    <parent link="base_link"/>
    <child link="camera_link2"/>
  </joint>

  <link name="camera_link2">
    <visual>
     <origin xyz="0 0 0" rpy="0 0 0"/>
      <geometry>
       <box size="0.02 0.02 0.02" />
      </geometry>
    </visual>
  </link>
  
  <joint name="camera_rgb_joint2" type="fixed">
    <origin xyz="${r200_cam_rgb_px} ${r200_cam_rgb_py} ${r200_cam_rgb_pz}" rpy="0 0 0"/>
    <parent link="camera_link2"/>
    <child link="camera_rgb_frame2"/>
  </joint>
  <link name="camera_rgb_frame2"/>

  <joint name="camera_rgb_optical_joint2" type="fixed">
    <origin xyz="0 0 0" rpy="-1.57 0 -1.57"/>
    <parent link="camera_rgb_frame2"/>
    <child link="camera_rgb_optical_frame2"/>
  </joint>
  <link name="camera_rgb_optical_frame2"/>

  <joint name="camera_depth_joint2" type="fixed">
    <origin xyz="${r200_cam_rgb_px} ${r200_cam_rgb_py + r200_cam_depth_offset} ${r200_cam_rgb_pz}" rpy="0 0 0"/>
    <parent link="camera_link2"/>
    <child link="camera_depth_frame2"/>
  </joint>
  <link name="camera_depth_frame2"/>

  <joint name="camera_depth_optical_joint2" type="fixed">
    <origin xyz="0 0 0" rpy="-1.57 0 -1.57"/>
    <parent link="camera_depth_frame2"/>
    <child link="camera_depth_optical_frame2"/>
  </joint>
  <link name="camera_depth_optical_frame2"/>
  
  <transmission name="1_suspension_act">
		<type>transmission_interface/SimpleTransmission</type>
		<joint name="suspension_joint1">
			<hardwareInterface>hardware_interface/EffortJointInterface</hardwareInterface>
		</joint>
		<actuator name="linear1">
			<hardwareInterface>hardware_interface/EffortJointInterface</hardwareInterface>
			<mechanicalReduction>1</mechanicalReduction>
		</actuator>
  </transmission>
	
  <transmission name="2_suspension_act">
		<type>transmission_interface/SimpleTransmission</type>
		<joint name="suspension_joint2">
			<hardwareInterface>hardware_interface/EffortJointInterface</hardwareInterface>
		</joint>
		<actuator name="linear2">
			<hardwareInterface>hardware_interface/EffortJointInterface</hardwareInterface>
			<mechanicalReduction>1</mechanicalReduction>
		</actuator>
	</transmission>
	
  <transmission name="3_suspension_act">
		<type>transmission_interface/SimpleTransmission</type>
		<joint name="suspension_joint3">
			<hardwareInterface>hardware_interface/EffortJointInterface</hardwareInterface>
		</joint>
		<actuator name="linear3">
			<hardwareInterface>hardware_interface/EffortJointInterface</hardwareInterface>
			<mechanicalReduction>1</mechanicalReduction>
		</actuator>
	</transmission>
	
	
  <transmission name="1_wheel_act">
		<type>transmission_interface/SimpleTransmission</type>
		<joint name="wheel_joint1">
			<hardwareInterface>hardware_interface/EffortJointInterface</hardwareInterface>
		</joint>
		<actuator name="rotate1">
			<hardwareInterface>hardware_interface/EffortJointInterface</hardwareInterface>
			<mechanicalReduction>1</mechanicalReduction>
		</actuator>
	</transmission>
	
	<transmission name="2_wheel_act">
		<type>transmission_interface/SimpleTransmission</type>
		<joint name="wheel_joint2">
			<hardwareInterface>hardware_interface/EffortJointInterface</hardwareInterface>
		</joint>
		<actuator name="rotate2">
			<hardwareInterface>hardware_interface/EffortJointInterface</hardwareInterface>
			<mechanicalReduction>1</mechanicalReduction>
		</actuator>
	</transmission>
	
    <gazebo>
		<plugin name="gazebo_ros_control" filename="libgazebo_ros_control.so">
			<robotNamespace>/myrobot</robotNamespace>
			<robotSimType>gazebo_ros_control/DefaultRobotHWSim</robotSimType>
		</plugin>
	</gazebo>
</robot>
